Workbook

Sheet COSTING
C1: # | D1: DAYS | E1: KMS | F1: TRUCK | N1: TRAILER | R1: OVERHEADS | Z1: TOTAL COST | AA1: PROFIT AMOUNT | AB1: REVENUE PER VEHICLE | AE1: =TODAY() -> 25569.083
B2: CLIENT | F2: FIXED | J2: VARIABLE | N2: FIXED | Q2: FIXED | R2: FIXED | T2: VARIABLE | U2: Profit Margin | V2: cpk on Cost | W2: cpk on Revenue | X2: TOTAL FIXED COST | Y2: TOTAL VARIABLE COST | AC2: PPK | AD2: RATE CARD INFO
B3: LOADING POINT: | F3: HP / DEPR | G3: TRACKING | H3: LICENCE | I3: INSURANCE | J3: R&M | K3: BREAKDOWNS | L3: DIESEL | M3: TOLLS | N3: HP / DEPR | O3: LICENCE | P3: INSURANCE | Q3: X-BRDR | R3: ADMIN | S3: DRIVER / BASIC | T3: OVERTIME & ALLOW | AD3: FUEL R | AE3: BASE R | AF3: TRANSPORT | AG3: EXTRA STOP | AH3: TOTAL TRANSPORT | AI3: EMPTY KM
A4: 1 | B4: TAUTLINER | C4: 1 | D4: =_xlfn.IFS(E4<200,0.5,E4<750,1,E4<1125,1.5,E4<1500,2,E4<1875,2.5,E4<2250,3,E4<2625,3.5,E4<3000,4,E4<3375,4.5) | E4: 420 | F4: 22000 | G4: 1800 | H4: 1295.87 | I4: =SUM(6350+5755+160) | J4: 1.65 | K4: 0.06 | L4: =VLOOKUP($B$37,'FUEL TABLE'!B:K,4,FALSE) | M4: 1.15 | N4: 12000 | O4: 1695 | P4: 1270 | Q4: 0 | R4: 28000 | S4: =SUM(14253+2256)*1.04*1.3 | T4: 1.7 | U4: =SUM(AA4/AB4) | V4: =SUM(Z4/E4) | W4: =SUM(AB4/E4) | X4: =SUM(F4+G4+H4+I4+N4+O4+P4+R4+S4)/25*D4 | Y4: =SUM(J4+L4+M4+Q4+T4+K4) | Z4: =SUM(X4+SUM(Y4*E4)) | AA4: =SUM(AC4*E4) | AB4: =SUM(Z4:AA4) | AC4: 3 | AD4: =ROUNDUP(SUM(E4*L4),-1) | AE4: =SUM(AF4-AD4) | AF4: =ROUNDUP(AB4,-1) | AH4: =+AF4+AG4
D5: .
A6: 2 | B6: TAUT X-BRDER - BOTSWANA | C6: 1 | D6: =_xlfn.IFS(E6<200,0.5,E6<750,1,E6<1125,1.5,E6<1500,2,E6<1875,2.5,E6<2250,3,E6<2625,3.5,E6<3000,4,E6<3375,4.5)+1 | E6: =SUM(405*2) | F6: 10000 | G6: 1800 | H6: =SUM(1565.22+17340)/12 | I6: =SUM(6350+5755+160) | J6: 1.65 | K6: 0.06 | L6: =VLOOKUP($B$37,'FUEL TABLE'!B:K,4,FALSE) | M6: =SUM(605/810) | N6: 12000 | O6: 1695 | P6: 1270 | Q6: 650 | R6: 28000 | S6: =SUM(14253+2256)*1.04*1.3 | T6: 1.7 | U6: =SUM(AA6/AB6) | V6: =SUM(Z6/E6) | W6: =SUM(AB6/E6) | X6: =SUM(F6+G6+H6+I6+N6+O6+P6+R6+S6)/25*D6 | Y6: =SUM(J6+L6+M6+T6+K6) | Z6: =SUM(X6+SUM(Y6*E6))+Q6 | AA6: =SUM(AC6*E6) | AB6: =SUM(Z6:AA6) | AC6: 5 | AD6: =ROUNDUP(SUM(E6*L6),-1) | AE6: =SUM(AF6-AD6) | AF6: =ROUNDUP(AB6,-1) | AH6: =+AF6+AG6
A8: 3 | B8: TAUT X-BRDER - NAMIBIA | C8: 1 | D8: =_xlfn.IFS(E8<200,0.5,E8<750,1,E8<1125,1.5,E8<1500,2,E8<1875,2.5,E8<2250,3,E8<2625,3.5,E8<3000,4,E8<3375,4.5)+1 | E8: 2100 | F8: 10000 | G8: 1800 | H8: =SUM(1565.22+17340)/12 | I8: =SUM(6350+5755+160) | J8: 1.65 | K8: 0.06 | L8: =VLOOKUP($B$37,'FUEL TABLE'!B:K,4,FALSE) | M8: =SUM(3100/2100) | N8: 12000 | O8: 1695 | P8: 1270 | Q8: 1500 | R8: 28000 | S8: =SUM(14253+2256)*1.04*1.3 | T8: 1.7 | U8: =SUM(AA8/AB8) | V8: =SUM(Z8/E8) | W8: =SUM(AB8/E8) | X8: =SUM(F8+G8+H8+I8+N8+O8+P8+R8+S8)/25*D8 | Y8: =SUM(J8+L8+M8+T8+K8) | Z8: =SUM(X8+SUM(Y8*E8))+Q8 | AA8: =SUM(AC8*E8) | AB8: =SUM(Z8:AA8) | AC8: 5 | AD8: =ROUNDUP(SUM(E8*L8),-1) | AE8: =SUM(AF8-AD8) | AF8: =ROUNDUP(AB8,-1) | AH8: =+AF8+AG8
A10: 4 | B10: CITRUS LOAD (+1 DAY STANDING FPT) | C10: 1 | D10: =_xlfn.IFS(E10<200,0.5,E10<750,1,E10<1125,1.5,E10<1500,2,E10<1875,2.5,E10<2250,3,E10<2625,3.5,E10<3000,4,E10<3375,4.5)+1 | E10: 100 | F10: 22000 | G10: 1800 | H10: 1295.87 | I10: =SUM(6350+5755+160) | J10: 1.65 | K10: 0.06 | L10: =VLOOKUP($B$37,'FUEL TABLE'!B:K,4,FALSE) | M10: 1.52 | N10: 12000 | O10: 1695 | P10: 1270 | Q10: 0 | R10: 28000 | S10: =SUM(14253+2256)*1.04*1.3 | T10: 1.7 | U10: =SUM(AA10/AB10) | V10: =SUM(Z10/E10) | W10: =SUM(AB10/E10) | X10: =SUM(F10+G10+H10+I10+N10+O10+P10+R10+S10)/25*D10 | Y10: =SUM(J10+L10+M10+Q10+T10+K10) | Z10: =SUM(X10+SUM(Y10*E10)) | AA10: =SUM(AC10*E10) | AB10: =SUM(Z10:AA10) | AC10: 5 | AD10: =ROUNDUP(SUM(E10*L10),-1) | AE10: =SUM(AF10-AD10) | AF10: =ROUNDUP(AB10,-1) | AH10: =+AF10+AG10
A12: 5 | B12: 14M/15M COMBO (NEW) | C12: 1 | D12: =_xlfn.IFS(E12<200,0.5,E12<750,1,E12<1125,1.5,E12<1500,2,E12<1875,2.5,E12<2250,3,E12<2625,3.5,E12<3000,4,E12<3375,4.5) | E12: 100 | F12: 22000 | G12: 1800 | H12: 1295.87 | I12: =SUM(6350+5755+160) | J12: 0.9 | K12: 0.06 | L12: =VLOOKUP($B$37,'FUEL TABLE'!B:K,5,FALSE) | M12: 0.82 | N12: 8000 | O12: 1406 | P12: 650 | Q12: 0 | R12: 22000 | S12: =SUM(14253+2256)*1.04*1.3 | T12: 1.3 | U12: =SUM(AA12/AB12) | V12: =SUM(Z12/E12) | W12: =SUM(AB12/E12) | X12: =SUM(F12+G12+H12+I12+N12+O12+P12+R12+S12)/25*D12 | Y12: =SUM(J12+L12+M12+Q12+T12+K12) | Z12: =SUM(X12+SUM(Y12*E12)) | AA12: =SUM(AC12*E12) | AB12: =SUM(Z12:AA12) | AC12: 5 | AD12: =ROUNDUP(SUM(E12*L12),-1) | AE12: =SUM(AF12-AD12) | AF12: =ROUNDUP(AB12,-1) | AH12: =+AF12+AG12
A14: 6 | B14: 14M/15M REEFER | C14: 1 | D14: =_xlfn.IFS(E14<200,0.5,E14<750,1,E14<1125,1.5,E14<1500,2,E14<1875,2.5,E14<2250,3,E14<2625,3.5,E14<3000,4,E14<3375,4.5) | E14: 100 | F14: 22000 | G14: 1800 | H14: 1295.87 | I14: =SUM(6350+5755+160) | J14: 0.9 | K14: 0.06 | L14: =VLOOKUP($B$37,'FUEL TABLE'!B:K,5,FALSE)+0.8 | M14: 0.82 | N14: 27000 | O14: 1406 | P14: 1533 | Q14: 0 | R14: 22000 | S14: =SUM(14253+2256)*1.04*1.3 | T14: 1.3 | U14: =SUM(AA14/AB14) | V14: =SUM(Z14/E14) | W14: =SUM(AB14/E14) | X14: =SUM(F14+G14+H14+I14+N14+O14+P14+R14+S14)/25*D14 | Y14: =SUM(J14+L14+M14+Q14+T14+K14) | Z14: =SUM(X14+SUM(Y14*E14)) | AA14: =SUM(AC14*E14) | AB14: =SUM(Z14:AA14) | AC14: 5 | AD14: =ROUNDUP(SUM(E14*L14),-1) | AE14: =SUM(AF14-AD14) | AF14: =ROUNDUP(AB14,-1) | AH14: =+AF14+AG14
A16: 7 | B16: 9 METER (NEW) | C16: 1 | D16: =_xlfn.IFS(E16<200,0.5,E16<750,1,E16<1125,1.5,E16<1500,2,E16<1875,2.5,E16<2250,3,E16<2625,3.5,E16<3000,4,E16<3375,4.5) | E16: 100 | F16: 26000 | G16: 1800 | H16: =SUM(766+259) | I16: =SUM(5700+3125+160) | J16: 1 | K16: 0.06 | L16: =VLOOKUP($B$37,'FUEL TABLE'!B:M,7,FALSE) | M16: 0.23 | N16: 8000 | O16: 600 | P16: 950 | Q16: 0 | R16: 15954 | S16: =SUM(14253+2256)*1.04*1.3 | T16: 2.21 | U16: =SUM(AA16/AB16) | V16: =SUM(Z16/E16) | W16: =AB16/E16 | X16: =SUM(F16+G16+H16+I16+N16+O16+P16+R16+S16)/30*D16 | Y16: =SUM(J16+L16+M16+Q16+T16+K16) | Z16: =SUM(X16+SUM(Y16*E16)) | AA16: =SUM(AC16*E16) | AB16: =SUM(Z16:AA16) | AC16: 5 | AD16: =ROUNDUP(SUM(E16*L16),-1) | AE16: =SUM(AF16-AD16) | AF16: =ROUNDUP(AB16,-1) | AH16: =+AF16+AG16
A18: 8 | B18: 8T JHB (NEW - EPS) | C18: 1 | D18: =_xlfn.IFS(E18<200,0.5,E18<750,1,E18<1125,1.5,E18<1500,2,E18<1875,2.5,E18<2250,3,E18<2625,3.5,E18<3000,4,E18<3375,4.5) | E18: 331 | F18: 22162 | G18: 1358 | H18: =SUM(782.61+9696)/12 | I18: =SUM(4913+3125+160) | J18: 1 | K18: 0.06 | L18: =VLOOKUP($B$37,'FUEL TABLE'!B:M,9,FALSE) | M18: 0.15 | N18: 0 | O18: 0 | P18: 0 | Q18: 0 | R18: 13620 | S18: =SUM(14253+2256)*1.04*1.3 | T18: 1.71 | U18: =SUM(AA18/AB18) | V18: =SUM(Z18/E18) | W18: =AB18/E18 | X18: =SUM(F18+G18+H18+I18+N18+O18+P18+R18+S18)/30*D18 | Y18: =SUM(J18+L18+M18+Q18+T18+K18) | Z18: =SUM(X18+SUM(Y18*E18)) | AA18: =SUM(AC18*E18) | AB18: =SUM(Z18:AA18) | AC18: 3 | AD18: =ROUNDUP(SUM(E18*L18),-1) | AE18: =SUM(AF18-AD18) | AF18: =ROUNDUP(AB18,-1) | AH18: =+AF18+AG18
A20: 9 | B20: 8T JHB (NEW) - X-BRDER - MOZ | C20: 1 | D20: =_xlfn.IFS(E20<200,0.5,E20<750,1,E20<1125,1.5,E20<1500,2,E20<1875,2.5,E20<2250,3,E20<2625,3.5,E20<3000,4,E20<3375,4.5)+1 | E20: =SUM(545*2) | F20: 22162 | G20: 1358 | H20: =SUM(782.61+9696)/12 | I20: =SUM(4913+3125+160) | J20: 1 | K20: 0.06 | L20: =VLOOKUP($B$37,'FUEL TABLE'!B:M,9,FALSE) | M20: =SUM(1498/1090) | N20: 0 | O20: 0 | P20: 0 | Q20: 1500 | R20: 13620 | S20: =SUM(14253+2256)*1.04*1.3 | T20: 1.71 | U20: =SUM(AA20/AB20) | V20: =SUM(Z20/E20) | W20: =AB20/E20 | X20: =SUM(F20+G20+H20+I20+N20+O20+P20+R20+S20)/30*D20 | Y20: =SUM(J20+L20+M20+T20+K20) | Z20: =SUM(X20+SUM(Y20*E20))+Q20 | AA20: =SUM(AC20*E20) | AB20: =SUM(Z20:AA20) | AC20: 5.2949275 | AD20: =ROUNDUP(SUM(E20*L20),-1) | AE20: =SUM(AF20-AD20) | AF20: =ROUNDUP(AB20,-1) | AH20: =+AF20+AG20
A22: 10 | B22: 8T JHB (OLD) | C22: 1 | D22: =_xlfn.IFS(E22<200,0.5,E22<750,1,E22<1125,1.5,E22<1500,2,E22<1875,2.5,E22<2250,3,E22<2625,3.5,E22<3000,4,E22<3375,4.5) | E22: 250 | F22: 10000 | G22: 1358 | H22: =SUM(782.61+9696)/12 | I22: 3686 | J22: 1 | K22: 0.06 | L22: =VLOOKUP($B$37,'FUEL TABLE'!B:M,9,FALSE) | M22: 0.15 | N22: 0 | O22: 0 | P22: 0 | Q22: 0 | R22: 13620 | S22: =SUM(14253+2256)*1.04*1.3 | T22: 1.71 | U22: =SUM(AA22/AB22) | V22: =SUM(Z22/E22) | W22: =AB22/E22 | X22: =SUM(F22+G22+H22+I22+N22+O22+P22+R22+S22)/30*D22 | Y22: =SUM(J22+L22+M22+Q22+T22+K22) | Z22: =SUM(X22+SUM(Y22*E22)) | AA22: =SUM(AC22*E22) | AB22: =SUM(Z22:AA22) | AC22: 4 | AD22: =ROUNDUP(SUM(E22*L22),-1) | AE22: =SUM(AF22-AD22) | AF22: =ROUNDUP(AB22,-1) | AH22: =+AF22+AG22
A24: 11 | B24: 14 TON CURTAIN | C24: 1 | D24: =_xlfn.IFS(E24<200,0.5,E24<750,1,E24<1125,1.5,E24<1500,2,E24<1875,2.5,E24<2250,3,E24<2625,3.5,E24<3000,4,E24<3375,4.5) | E24: 100 | F24: 36500 | G24: 1150 | H24: 1234.16 | I24: =SUM(7350+3431+160) | J24: 0.7 | K24: 0.06 | L24: =VLOOKUP($B$37,'FUEL TABLE'!B:M,7,FALSE) | M24: 0.6 | N24: 0 | O24: 0 | P24: 0 | Q24: 0 | R24: 18288 | S24: =SUM(14253+2256)*1.04*1.3 | T24: 1.5 | U24: =SUM(AA24/AB24) | V24: =SUM(Z24/E24) | W24: =SUM(AB24/E24) | X24: =SUM(F24+G24+H24+I24+N24+O24+P24+R24+S24)/30*D24 | Y24: =SUM(J24+L24+M24+Q24+T24+K24) | Z24: =SUM(X24+SUM(Y24*E24)) | AA24: =SUM(AC24*E24) | AB24: =SUM(Z24:AA24) | AC24: 5 | AD24: =ROUNDUP(SUM(E24*L24),-1) | AE24: =SUM(AF24-AD24) | AF24: =ROUNDUP(AB24,-1) | AH24: =+AF24+AG24
A26: 12 | B26: 1TON BAKKIE | C26: 1 | D26: =_xlfn.IFS(E26<200,0.5,E26<750,1,E26<1125,1.5,E26<1500,2,E26<1875,2.5,E26<2250,3,E26<2625,3.5,E26<3000,4,E26<3375,4.5) | E26: =SUM(405*2) | F26: 2500 | G26: 1358 | H26: =SUM(782.61+9696)/12 | I26: 3686 | J26: 1 | K26: 0.06 | L26: =VLOOKUP($B$37,'FUEL TABLE'!B:M,11,FALSE) | M26: 0.15 | N26: 0 | O26: 0 | P26: 0 | Q26: 0 | R26: 10000 | S26: =SUM(14253+2256)*1.04*1.3 | T26: 1.71 | U26: =SUM(AA26/AB26) | V26: =SUM(Z26/E26) | W26: =AB26/E26 | X26: =SUM(F26+G26+H26+I26+N26+O26+P26+R26+S26)/30*D26 | Y26: =SUM(J26+L26+M26+Q26+T26+K26) | Z26: =SUM(X26+SUM(Y26*E26)) | AA26: =SUM(AC26*E26) | AB26: =SUM(Z26:AA26) | AC26: 1.5 | AD26: =ROUNDUP(SUM(E26*L26),-1) | AE26: =SUM(AF26-AD26) | AF26: =ROUNDUP(AB26,-1) | AH26: =+AF26+AG26
B28: INSTRUCTION:
A30: 1 | B30: Yellow = input cell
A31: 2 | B31: Change kms as per the route requirement
A32: 3 | B32: Change PPK as per what you (Ludwig / Evert) requires
A33: 4 | B33: Excel will calculate transport rate, show profit value and profit margin
B36: MONTH
B37: 45931
B39: NOTES:
B40: HP CALCULATED AT NEW VEHICLE PRICE 70% NEW 30% OLD
B41: DRIVER WAGES INCREASED 7.5% ACROSS ALL

Sheet FUEL TABLE
B2: FUEL LEVY - REEF- JHB RDC
B4: FUEL CONSUMPTION KM/L | E4: 2 | F4: 2.3 | G4: 2.3 | H4: 3.5 | I4: 3.5 | J4: 4 | K4: 4 | L4: 10 | M4: 8 | N4: 4.5 | R4: AUGUST | V4: SEPTEMBER | Z4: OCTOBER
P5: type | Q5: qty | R5: qty | S5: revenue | T5: Contr. | U5: value per h | V5: qty | W5: revenue | X5: contr. | Y5: value per h | Z5: qty | AA5: revenue | AB5: contr. | AC5: value per h
B6: MONTH | C6: Fuel Price | D6: % change | E6: LINK | F6: 15M | G6: REEFER | H6: 14TON | I6: 9M | J6: 8TON | K6: 4TON | L6: 1TON | M6: REV.LOG | N6: 2.8TON | P6: Bakkies | R6: 4 | S6: 4000 | T6: =SUM(S6/$S$14) | U6: =IFERROR(SUM(T6*$U$14)/R6,0)
B7: 43678 | C7: 14.37 | E7: =SUM($C7/$E$4) | F7: =SUM($C7/$F$4) | H7: =SUM($C7/$H$4) | I7: =SUM($C7/$I$4) | J7: =SUM($C7/$J$4) | K7: =SUM($C7/$K$4) | L7: =SUM($C7/$L$4) | M7: =SUM($C7/$M$4) | P7: 1.5ton | R7: 7 | S7: 675944 | T7: =SUM(S7/$S$14) | U7: =IFERROR(SUM(T7*$U$14)/R7,0)
B8: 43709 | C8: =SUM(C7+0.33) | D8: =SUM(C8-C7)/C7 | E8: =SUM($C8/$E$4) | F8: =SUM($C8/$F$4) | H8: =SUM($C8/$H$4) | I8: =SUM($C8/$I$4) | J8: =SUM($C8/$J$4) | K8: =SUM($C8/$K$4) | L8: =SUM($C8/$L$4) | M8: =SUM($C8/$M$4) | P8: 5ton | S8: 0 | T8: =SUM(S8/$S$14) | U8: =IFERROR(SUM(T8*$U$14)/R8,0)
B9: 43739 | C9: =SUM(C8+0.25) | D9: =SUM(C9-C8)/C8 | E9: =SUM($C9/$E$4) | F9: =SUM($C9/$F$4) | H9: =SUM($C9/$H$4) | I9: =SUM($C9/$I$4) | J9: =SUM($C9/$J$4) | K9: =SUM($C9/$K$4) | L9: =SUM($C9/$L$4) | M9: =SUM($C9/$M$4) | P9: 8ton | R9: =2+2+10+5+6+1 | S9: =SUM(121711+118975+170969+289249+339603+36847) | T9: =SUM(S9/$S$14) | U9: =IFERROR(SUM(T9*$U$14)/R9,0)
B10: 43770 | C10: =SUM(C9-0.14) | D10: =SUM(C10-C9)/C9 | E10: =SUM($C10/$E$4) | F10: =SUM($C10/$F$4) | H10: =SUM($C10/$H$4) | I10: =SUM($C10/$I$4) | J10: =SUM($C10/$J$4) | K10: =SUM($C10/$K$4) | L10: =SUM($C10/$L$4) | M10: =SUM($C10/$M$4) | P10: 9m | R10: =3+7 | S10: =SUM(110534+440590) | T10: =SUM(S10/$S$14) | U10: =IFERROR(SUM(T10*$U$14)/R10,0)
B11: 43800 | C11: =SUM(C10-0.22) | D11: =SUM(C11-C10)/C10 | E11: =SUM($C11/$E$4) | F11: =SUM($C11/$F$4) | H11: =SUM($C11/$H$4) | I11: =SUM($C11/$I$4) | J11: =SUM($C11/$J$4) | K11: =SUM($C11/$K$4) | L11: =SUM($C11/$L$4) | M11: =SUM($C11/$M$4) | P11: 14ton | R11: 4 | S11: =SUM(396280) | T11: =SUM(S11/$S$14) | U11: =IFERROR(SUM(T11*$U$14)/R11,0)
B12: 43831 | C12: 14.68 | D12: =SUM(C12-C11)/C11 | E12: =SUM($C12/$E$4) | F12: =SUM($C12/$F$4) | H12: =SUM($C12/$H$4) | I12: =SUM($C12/$I$4) | J12: =SUM($C12/$J$4) | K12: =SUM($C12/$K$4) | L12: =SUM($C12/$L$4) | M12: =SUM($C12/$M$4) | P12: 15m | R12: =1+3+12+1+19 | S12: =SUM(134770+392618+2131973+194005+3081993) | T12: =SUM(S12/$S$14) | U12: =IFERROR(SUM(T12*$U$14)/R12,0)
B13: 43862 | C13: 14.63 | D13: =SUM(C13-C12)/C12 | E13: =SUM($C13/$E$4) | F13: =SUM($C13/$F$4) | H13: =SUM($C13/$H$4) | I13: =SUM($C13/$I$4) | J13: =SUM($C13/$J$4) | K13: =SUM($C13/$K$4) | L13: =SUM($C13/$L$4) | M13: =SUM($C13/$M$4) | P13: Link | R13: =3+48+3+4 | S13: =SUM(464703+7672063+451646+745332) | T13: =SUM(S13/$S$14) | U13: =IFERROR(SUM(T13*$U$14)/R13,0)
B14: 43891 | C14: =SUM(C13-0.54) | D14: =SUM(C14-C13)/C13 | E14: =SUM($C14/$E$4) | F14: =SUM($C14/$F$4) | H14: =SUM($C14/$H$4) | I14: =SUM($C14/$I$4) | J14: =SUM($C14/$J$4) | K14: =SUM($C14/$K$4) | L14: =SUM($C14/$L$4) | M14: =SUM($C14/$M$4) | Q14: =SUM(Q6:Q13) | R14: =SUM(R6:R13) | S14: =SUM(S6:S13) | T14: =SUM(T6:T13) | U14: 2536440
B15: 43922 | C15: =SUM(C14-1.34) | D15: =SUM(C15-C14)/C14 | E15: =SUM($C15/$E$4) | F15: =SUM($C15/$F$4) | H15: =SUM($C15/$H$4) | I15: =SUM($C15/$I$4) | J15: =SUM($C15/$J$4) | K15: =SUM($C15/$K$4) | L15: =SUM($C15/$L$4) | M15: =SUM($C15/$M$4)
B16: 43952 | C16: 11.19 | D16: =SUM(C16-C15)/C15 | E16: =SUM($C16/$E$4) | F16: =SUM($C16/$F$4) | H16: =SUM($C16/$H$4) | I16: =SUM($C16/$I$4) | J16: =SUM($C16/$J$4) | K16: =SUM($C16/$K$4) | L16: =SUM($C16/$L$4) | M16: =SUM($C16/$M$4)
B17: 43983 | C17: 11.4 | D17: =SUM(C17-C16)/C16 | E17: =SUM($C17/$E$4) | F17: =SUM($C17/$F$4) | H17: =SUM($C17/$H$4) | I17: =SUM($C17/$I$4) | J17: =SUM($C17/$J$4) | K17: =SUM($C17/$K$4) | L17: =SUM($C17/$L$4) | M17: =SUM($C17/$M$4)
B18: 44013 | C18: 13.0356 | D18: =SUM(C18-C17)/C17 | E18: =SUM($C18/$E$4) | F18: =SUM($C18/$F$4) | H18: =SUM($C18/$H$4) | I18: =SUM($C18/$I$4) | J18: =SUM($C18/$J$4) | K18: =SUM($C18/$K$4) | L18: =SUM($C18/$L$4) | M18: =SUM($C18/$M$4)
B19: 44044 | C19: 13.4856 | D19: =SUM(C19-C18)/C18 | E19: =SUM($C19/$E$4) | F19: =SUM($C19/$F$4) | H19: =SUM($C19/$H$4) | I19: =SUM($C19/$I$4) | J19: =SUM($C19/$J$4) | K19: =SUM($C19/$K$4) | L19: =SUM($C19/$L$4) | M19: =SUM($C19/$M$4)
B20: 44075 | C20: 13.2756 | D20: =SUM(C20-C19)/C19 | E20: =SUM($C20/$E$4) | F20: =SUM($C20/$F$4) | H20: =SUM($C20/$H$4) | I20: =SUM($C20/$I$4) | J20: =SUM($C20/$J$4) | K20: =SUM($C20/$K$4) | L20: =SUM($C20/$L$4) | M20: =SUM($C20/$M$4)
B21: 44105 | C21: 12.35 | D21: =SUM(C21-C20)/C20 | E21: =SUM($C21/$E$4) | F21: =SUM($C21/$F$4) | H21: =SUM($C21/$H$4) | I21: =SUM($C21/$I$4) | J21: =SUM($C21/$J$4) | K21: =SUM($C21/$K$4) | L21: =SUM($C21/$L$4) | M21: =SUM($C21/$M$4)
B22: 44136 | C22: 12.2556 | D22: =SUM(C22-C21)/C21 | E22: =SUM($C22/$E$4) | F22: =SUM($C22/$F$4) | H22: =SUM($C22/$H$4) | I22: =SUM($C22/$I$4) | J22: =SUM($C22/$J$4) | K22: =SUM($C22/$K$4) | L22: =SUM($C22/$L$4) | M22: =SUM($C22/$M$4)
B23: 44166 | C23: 12.4542 | D23: =SUM(C23-C22)/C22 | E23: =SUM($C23/$E$4) | F23: =SUM($C23/$F$4) | H23: =SUM($C23/$H$4) | I23: =SUM($C23/$I$4) | J23: =SUM($C23/$J$4) | K23: =SUM($C23/$K$4) | L23: =SUM($C23/$L$4) | M23: =SUM($C23/$M$4)
B24: 44202 | C24: 13.0042 | D24: =SUM(C24-C23)/C23 | E24: =SUM($C24/$E$4) | F24: =SUM($C24/$F$4) | H24: =SUM($C24/$H$4) | I24: =SUM($C24/$I$4) | J24: =SUM($C24/$J$4) | K24: =SUM($C24/$K$4) | L24: =SUM($C24/$L$4) | M24: =SUM($C24/$M$4)
B25: 44233 | C25: 13.5842 | D25: =SUM(C25-C24)/C24 | E25: =SUM($C25/$E$4) | F25: =SUM($C25/$F$4) | H25: =SUM($C25/$H$4) | I25: =SUM($C25/$I$4) | J25: =SUM($C25/$J$4) | K25: =SUM($C25/$K$4) | L25: =SUM($C25/$L$4) | M25: =SUM($C25/$M$4)
B26: 44261 | C26: 14.1242 | D26: =SUM(C26-C25)/C25 | E26: =SUM($C26/$E$4) | F26: =SUM($C26/$F$4) | H26: =SUM($C26/$H$4) | I26: =SUM($C26/$I$4) | J26: =SUM($C26/$J$4) | K26: =SUM($C26/$K$4) | L26: =SUM($C26/$L$4) | M26: =SUM($C26/$M$4)
B27: 44292 | C27: 14.7762 | D27: =SUM(C27-C26)/C26 | E27: =SUM($C27/$E$4) | F27: =SUM($C27/$F$4) | H27: =SUM($C27/$H$4) | I27: =SUM($C27/$I$4) | J27: =SUM($C27/$J$4) | K27: =SUM($C27/$K$4) | L27: =SUM($C27/$L$4) | M27: =SUM($C27/$M$4)
... B32: 44445 | C32: 15.4898 | D32: =SUM(C32-C31)/C31 | E32: =SUM($C32/$E$4) | F32: =SUM($C32/$F$4) | H32: =SUM($C32/$H$4) | I32: =SUM($C32/$I$4) | J32: =SUM($C32/$J$4) | K32: =SUM($C32/$K$4) | L32: =SUM($C32/$L$4) | M32: =SUM($C32/$M$4)
B33: 44475 | C33: 15.7178 | D33: =SUM(C33-C32)/C32 | E33: =SUM($C33/$E$4) | F33: =SUM($C33/$F$4) | H33: =SUM($C33/$H$4) | I33: =SUM($C33/$I$4) | J33: =SUM($C33/$J$4) | K33: =SUM($C33/$K$4) | L33: =SUM($C33/$L$4) | M33: =SUM($C33/$M$4) | N33: =SUM($C33/$N$4)
B34: 44506 | C34: 17.1998 | D34: =SUM(C34-C33)/C33 | E34: =SUM($C34/$E$4) | F34: =SUM($C34/$F$4) | H34: =SUM($C34/$H$4) | I34: =SUM($C34/$I$4) | J34: =SUM($C34/$J$4) | K34: =SUM($C34/$K$4) | L34: =SUM($C34/$L$4) | M34: =SUM($C34/$M$4) | N34: =SUM($C34/$N$4)
B35: 44536 | C35: 17.9248 | D35: =SUM(C35-C34)/C34 | E35: =SUM($C35/$E$4) | F35: =SUM($C35/$F$4) | H35: =SUM($C35/$H$4) | I35: =SUM($C35/$I$4) | J35: =SUM($C35/$J$4) | K35: =SUM($C35/$K$4) | L35: =SUM($C35/$L$4) | M35: =SUM($C35/$M$4) | N35: =SUM($C35/$N$4)
B36: 44567 | C36: =SUM(C35-0.698) | D36: =SUM(C36-C35)/C35 | E36: =SUM($C36/$E$4) | F36: =SUM($C36/$F$4) | H36: =SUM($C36/$H$4) | I36: =SUM($C36/$I$4) | J36: =SUM($C36/$J$4) | K36: =SUM($C36/$K$4) | L36: =SUM($C36/$L$4) | M36: =SUM($C36/$M$4) | N36: =SUM($C36/$N$4)
B37: 44598 | C37: 18.0452 | D37: =SUM(C37-C36)/C36 | E37: =SUM($C37/$E$4) | F37: =SUM($C37/$F$4) | H37: =SUM($C37/$H$4) | I37: =SUM($C37/$I$4) | J37: =SUM($C37/$J$4) | K37: =SUM($C37/$K$4) | L37: =SUM($C37/$L$4) | M37: =SUM($C37/$M$4) | N37: =SUM($C37/$N$4)
B38: 44626 | C38: 19.4888 | D38: =SUM(C38-C37)/C37 | E38: =SUM($C38/$E$4) | F38: =SUM($C38/$F$4) | H38: =SUM($C38/$H$4) | I38: =SUM($C38/$I$4) | J38: =SUM($C38/$J$4) | K38: =SUM($C38/$K$4) | L38: =SUM($C38/$L$4) | M38: =SUM($C38/$M$4) | N38: =SUM($C38/$N$4)
B39: 44657 | C39: 21.0144 | D39: =SUM(C39-C38)/C38 | E39: =SUM($C39/$E$4) | F39: =SUM($C39/$F$4) | H39: =SUM($C39/$H$4) | I39: =SUM($C39/$I$4) | J39: =SUM($C39/$J$4) | K39: =SUM($C39/$K$4) | L39: =SUM($C39/$L$4) | M39: =SUM($C39/$M$4) | N39: =SUM($C39/$N$4)
B40: 44687 | C40: =SUM(C39+0.98) | D40: =SUM(C40-C39)/C39 | E40: =SUM($C40/$E$4) | F40: =SUM($C40/$F$4) | H40: =SUM($C40/$H$4) | I40: =SUM($C40/$I$4) | J40: =SUM($C40/$J$4) | K40: =SUM($C40/$K$4) | L40: =SUM($C40/$L$4) | M40: =SUM($C40/$M$4) | N40: =SUM($C40/$N$4)
B41: 44718 | C41: 23.0944 | D41: =SUM(C41-C40)/C40 | E41: =SUM($C41/$E$4) | F41: =SUM($C41/$F$4) | H41: =SUM($C41/$H$4) | I41: =SUM($C41/$I$4) | J41: =SUM($C41/$J$4) | K41: =SUM($C41/$K$4) | L41: =SUM($C41/$L$4) | M41: =SUM($C41/$M$4) | N41: =SUM($C41/$N$4)
B42: 44748 | C42: 25.4044 | D42: =SUM(C42-C41)/C41 | E42: =SUM($C42/$E$4) | F42: =SUM($C42/$F$4) | H42: =SUM($C42/$H$4) | I42: =SUM($C42/$I$4) | J42: =SUM($C42/$J$4) | K42: =SUM($C42/$K$4) | L42: =SUM($C42/$L$4) | M42: =SUM($C42/$M$4) | N42: =SUM($C42/$N$4)
B43: 44779 | C43: 24.5244 | D43: =SUM(C43-C42)/C42 | E43: =SUM($C43/$E$4) | F43: =SUM($C43/$F$4) | H43: =SUM($C43/$H$4) | I43: =SUM($C43/$I$4) | J43: =SUM($C43/$J$4) | K43: =SUM($C43/$K$4) | L43: =SUM($C43/$L$4) | M43: =SUM($C43/$M$4) | N43: =SUM($C43/$N$4)
B44: 44810 | C44: 23.961 | D44: =SUM(C44-C43)/C43 | E44: =SUM($C44/$E$4) | F44: =SUM($C44/$F$4) | H44: =SUM($C44/$H$4) | I44: =SUM($C44/$I$4) | J44: =SUM($C44/$J$4) | K44: =SUM($C44/$K$4) | L44: =SUM($C44/$L$4) | M44: =SUM($C44/$M$4) | N44: =SUM($C44/$N$4)
B45: 44840 | C45: 24.061 | D45: =SUM(C45-C44)/C44 | E45: =SUM($C45/$E$4) | F45: =SUM($C45/$F$4) | H45: =SUM($C45/$H$4) | I45: =SUM($C45/$I$4) | J45: =SUM($C45/$J$4) | K45: =SUM($C45/$K$4) | L45: =SUM($C45/$L$4) | M45: =SUM($C45/$M$4) | N45: =SUM($C45/$N$4)
B46: 44871 | C46: 25.4896 | D46: =SUM(C46-C45)/C45 | E46: =SUM($C46/$E$4) | F46: =SUM($C46/$F$4) | H46: =SUM($C46/$H$4) | I46: =SUM($C46/$I$4) | J46: =SUM($C46/$J$4) | K46: =SUM($C46/$K$4) | L46: =SUM($C46/$L$4) | M46: =SUM($C46/$M$4) | N46: =SUM($C46/$N$4)
...

Sheet P&amp;L
A2: CURRENT STATUS QUO
A3: FIXED COSTS | D3: 3105000
B5: COUNT | C5: RATE | D5: VALUE | E5: P.DAY
A6: LINKS | B6: 60 | C6: 28000 | D6: =SUM(C6*B6) | E6: =SUM(C6/25)
A7: 14METER | B7: 18 | C7: 22000 | D7: =SUM(C7*B7) | E7: =SUM(C7/25)
A8: 14TON | B8: 2 | C8: 18288 | D8: =SUM(C8*B8) | E8: =SUM(C8/25)
A9: 9METERS | B9: 10 | C9: 16000 | D9: =SUM(C9*B9) | E9: =SUM(C9/25)
A10: 8TON | B10: 17 | C10: 13620 | D10: =SUM(C10*B10) | E10: =SUM(C10/25)
A11: SHUNTER | B11: =SUM(1+1+1+1+1+4) | C11: 2500 | D11: =SUM(C11*B11) | E11: =SUM(C11/25)
B12: =SUM(B6:B11) | D12: =SUM(D6:D11)
A13: VARIANCE | D13: =SUM(D3-D12)
A15: SIMLUATION #1
A16: FIXED COSTS | D16: =D3
B18: COUNT | C18: RATE | D18: VALUE | E18: P.DAY
A19: LINKS | B19: 60 | C19: 34000 | D19: =SUM(C19*B19) | E19: =SUM(C19/25)
A20: 14METER | B20: 18 | C20: 28000 | D20: =SUM(C20*B20) | E20: =SUM(C20/25)
A21: 14TON | B21: 2 | C21: 20000 | D21: =SUM(C21*B21) | E21: =SUM(C21/25)
A22: 9METERS | B22: 10 | C22: 22000 | D22: =SUM(C22*B22) | E22: =SUM(C22/25)
A23: 8TON | B23: 17 | C23: 16000 | D23: =SUM(C23*B23) | E23: =SUM(C23/25)
A24: SHUNTER | B24: =SUM(1+1+1+1+1+4) | C24: 2500 | D24: =SUM(C24*B24) | E24: =SUM(C24/25)
B25: =SUM(B19:B24) | D25: =SUM(D19:D24)
A26: VARIANCE | D26: =SUM(D16-D25)
